package com.proyecto.java8.CompletableFurute;

import java.util.concurrent.CompletableFuture;
import java.util.concurrent.ExecutorService;
import java.util.concurrent.Executors;
import java.util.logging.Logger;

public class CompletableFuture18 {

	private static final ExecutorService executor = Executors.newCachedThreadPool();
	private static final Logger LOGGER = Logger.getLogger(Logger.GLOBAL_LOGGER_NAME);
	
	CompletableFuture<String> futureAsync = CompletableFuture.supplyAsync(() -> {
	    LOGGER.info("Comenzando supplyAsync with exception...");
	    Sleep(2);
	    LOGGER.info("Terminado supplyAsync with exception!");
	    throw new RuntimeException("Error en el futuro");
	    //return "bueno";
	}, executor);
	 
	CompletableFuture<String> futureEx = futureAsync.exceptionally(e -> {
	    LOGGER.warning("Resultado con excepciÃ³n!!");
	    return "Entro a la excepcion.";
	});
	 
	public void llamarMetodo(){
		futureEx.whenCompleteAsync((s, e) -> LOGGER.info("Resultado futureEx: "+ s),
		        executor);
	}
	
	public static void main(String[] args) {
		CompletableFuture18 app = new CompletableFuture18();
		app.llamarMetodo();
	}
	
	
	private void Sleep(int i) {
		try{
			int finalx = i * 1000;
			int x = 0;
			while (x < finalx) {
				System.out.println(x);
				Thread.sleep(1000);
				x = x + 1000;				 
			}		
		}catch(InterruptedException e){	}			
	}
}
